<?xml version="1.0" ?>
<!-- This file was generated by robot assembler -->
<robot name="wheeled_robot2"
       xmlns:xi="http://www.w3.org/2001/XInclude"
       xmlns:gazebo="http://playerstage.sourceforge.net/gazebo/xmlschema/#gz"
       xmlns:model="http://playerstage.sourceforge.net/gazebo/xmlschema/#model"
       xmlns:sensor="http://playerstage.sourceforge.net/gazebo/xmlschema/#sensor"
       xmlns:body="http://playerstage.sourceforge.net/gazebo/xmlschema/#body"
       xmlns:geom="http://playerstage.sourceforge.net/gazebo/xmlschema/#geom"
       xmlns:joint="http://playerstage.sourceforge.net/gazebo/xmlschema/#joint"
       xmlns:interface="http://playerstage.sourceforge.net/gazebo/xmlschema/#interface"
       xmlns:rendering="http://playerstage.sourceforge.net/gazebo/xmlschema/#rendering"
       xmlns:renderable="http://playerstage.sourceforge.net/gazebo/xmlschema/#renderable"
       xmlns:controller="http://playerstage.sourceforge.net/gazebo/xmlschema/#controller"
       xmlns:physics="http://playerstage.sourceforge.net/gazebo/xmlschema/#physics"
       xmlns:xacro="http://www.ros.org/wiki/xacro">
  <!-- <xacro:macro name="gazebo_link_reference" params="link_name mu1:=0.8 mu2:=0.8" > -->
  <xacro:macro name="gazebo_link_reference" params="link_name mu1:=1000.0 mu2:=1000.0" >
    <gazebo reference="${link_name}">
      <mu1>${mu1}</mu1>
      <mu2>${mu2}</mu2>
    </gazebo>
  </xacro:macro>
  <xacro:macro name="gazebo_transmission" params="joint_name" >
    <transmission name="${joint_name}_trans">
      <type>transmission_interface/SimpleTransmission</type>
      <joint name="${joint_name}">
        <!-- <hardwareInterface>hardware_interface/VelocityJointInterface</hardwareInterface> -->
        <hardwareInterface>hardware_interface/EffortJointInterface</hardwareInterface>
      </joint>
      <actuator name="${joint_name}_motor">
        <!-- <hardwareInterface>hardware_interface/VelocityJointInterface</hardwareInterface> -->
        <hardwareInterface>hardware_interface/EffortJointInterface</hardwareInterface>
        <mechanicalReduction>1</mechanicalReduction>
      </actuator>
    </transmission>
  </xacro:macro>

  <xacro:gazebo_link_reference link_name="BASE" />
  <link name="BASE">
  <inertial>
     <mass value="0.01"/>
     <!-- <mass value="0.32"/> -->
     <origin rpy="0 0 0" xyz="-1.110223e-17 1.278977e-17 -0.014062"/>
     <inertia ixx="0.00041" ixy="4.996004e-21" ixz="-4.074536e-20" iyy="0.000177" iyz="1.091394e-20" izz="0.000357"/>
  </inertial>
  <visual>
     <origin xyz="0.000000 0.000000 0.000000" rpy="0.00000000 -0.00000000 0.00000000"/>
     <geometry>
     <mesh filename="file:///home/y-kawamura/ros/new_ws/src/robot_assembler/meshes/body-parts-a.dae" scale="1.000000 1.000000 1.000000"/>
     </geometry>
  </visual>
  <collision>
     <origin xyz="0.000000 0.000000 0.000000" rpy="0.00000000 -0.00000000 0.00000000"/>
     <geometry>
     <mesh filename="file:///home/y-kawamura/ros/new_ws/src/robot_assembler/meshes/body-parts-a.dae" scale="1.000000 1.000000 1.000000"/>
     </geometry>
  </collision>
  <visual>
     <origin xyz="0.012000 -0.032000 -0.021000" rpy="3.14159265 0.00000000 1.57079633"/>
     <geometry>
     <mesh filename="file:///home/y-kawamura/ros/new_ws/src/robot_assembler/meshes/xm430_dynamixel.dae" scale="1.000000 1.000000 1.000000"/>
     </geometry>
  </visual>
  <collision>
     <origin xyz="0.012000 -0.032000 -0.021000" rpy="3.14159265 0.00000000 1.57079633"/>
     <geometry>
     <mesh filename="file:///home/y-kawamura/ros/new_ws/src/robot_assembler/meshes/xm430_dynamixel.dae" scale="1.000000 1.000000 1.000000"/>
     </geometry>
  </collision>
  <visual>
     <origin xyz="0.012000 0.032000 -0.021000" rpy="3.14159265 0.00000000 1.57079633"/>
     <geometry>
     <mesh filename="file:///home/y-kawamura/ros/new_ws/src/robot_assembler/meshes/xm430_dynamixel.dae" scale="1.000000 1.000000 1.000000"/>
     </geometry>
  </visual>
  <collision>
     <origin xyz="0.012000 0.032000 -0.021000" rpy="3.14159265 0.00000000 1.57079633"/>
     <geometry>
     <mesh filename="file:///home/y-kawamura/ros/new_ws/src/robot_assembler/meshes/xm430_dynamixel.dae" scale="1.000000 1.000000 1.000000"/>
     </geometry>
  </collision>
  </link>
  <xacro:gazebo_link_reference link_name="LINK0" />
  <link name="LINK0">
  <inertial>
     <mass value="0.015"/>
     <origin rpy="0 0 0" xyz="-2.131628e-17 5.329071e-18 0.01455"/>
     <inertia ixx="1.969763e-06" ixy="-6.539435e-22" ixz="-1.064176e-21" iyy="3.159763e-06" iyz="-6.260938e-37" izz="3.012500e-06"/>
  </inertial>
  <visual>
     <origin xyz="-0.000000 0.000000 0.028000" rpy="-1.57079633 0.00000000 -1.57079633"/>
     <geometry>
     <mesh filename="file:///home/y-kawamura/ros/new_ws/src/robot_assembler/meshes/fr12_h101.dae" scale="1.000000 1.000000 1.000000"/>
     </geometry>
  </visual>
  <collision>
     <origin xyz="-0.000000 0.000000 0.028000" rpy="-1.57079633 0.00000000 -1.57079633"/>
     <geometry>
     <mesh filename="file:///home/y-kawamura/ros/new_ws/src/robot_assembler/meshes/fr12_h101.dae" scale="1.000000 1.000000 1.000000"/>
     </geometry>
  </collision>
  </link>
  <xacro:gazebo_link_reference link_name="LINK1" />
  <link name="LINK1">
  <inertial>
     <mass value="0.212"/>
     <origin rpy="0 0 0" xyz="-0.000708 -0.012283 0.001288"/>
     <inertia ixx="0.000132" ixy="4.245283e-08" ixz="2.896769e-06" iyy="0.000116" iyz="-2.617925e-07" izz="5.942872e-05"/>
  </inertial>
  <visual>
     <origin xyz="0.000000 0.000000 -0.019000" rpy="0.00000000 -0.00000000 0.00000000"/>
     <geometry>
     <mesh filename="file:///home/y-kawamura/ros/new_ws/src/robot_assembler/meshes/xm430_dynamixel.dae" scale="1.000000 1.000000 1.000000"/>
     </geometry>
  </visual>
  <collision>
     <origin xyz="0.000000 0.000000 -0.019000" rpy="0.00000000 -0.00000000 0.00000000"/>
     <geometry>
     <mesh filename="file:///home/y-kawamura/ros/new_ws/src/robot_assembler/meshes/xm430_dynamixel.dae" scale="1.000000 1.000000 1.000000"/>
     </geometry>
  </collision>
  <visual>
     <origin xyz="0.000000 0.000000 -0.016000" rpy="1.57079633 0.00000000 0.00000000"/>
     <geometry>
     <mesh filename="file:///home/y-kawamura/ros/new_ws/src/robot_assembler/meshes/fr12_x102.dae" scale="1.000000 1.000000 1.000000"/>
     </geometry>
  </visual>
  <collision>
     <origin xyz="0.000000 0.000000 -0.016000" rpy="1.57079633 0.00000000 0.00000000"/>
     <geometry>
     <mesh filename="file:///home/y-kawamura/ros/new_ws/src/robot_assembler/meshes/fr12_x102.dae" scale="1.000000 1.000000 1.000000"/>
     </geometry>
  </collision>
  <visual>
     <origin xyz="0.000000 -0.000000 0.020600" rpy="-0.03118577 -1.57079633 0.03118577"/>
     <geometry>
     <mesh filename="file:///home/y-kawamura/ros/new_ws/src/robot_assembler/meshes/xm430_dynamixel.dae" scale="1.000000 1.000000 1.000000"/>
     </geometry>
  </visual>
  <collision>
     <origin xyz="0.000000 -0.000000 0.020600" rpy="-0.03118577 -1.57079633 0.03118577"/>
     <geometry>
     <mesh filename="file:///home/y-kawamura/ros/new_ws/src/robot_assembler/meshes/xm430_dynamixel.dae" scale="1.000000 1.000000 1.000000"/>
     </geometry>
  </collision>
  </link>
  <xacro:gazebo_link_reference link_name="LINK2" />
  <link name="LINK2">
  <inertial>
     <mass value="0.134"/>
     <origin rpy="0 0 0" xyz="2.033001e-16 -0.072683 -0.017881"/>
     <inertia ixx="9.582042e-05" ixy="2.498054e-19" ixz="-2.083772e-20" iyy="2.736267e-05" iyz="1.622575e-06" izz="8.942792e-05"/>
  </inertial>
  <visual>
     <origin xyz="0.000000 0.000000 -0.019000" rpy="0.61547971 1.57079633 -2.52611294"/>
     <geometry>
     <mesh filename="file:///home/y-kawamura/ros/new_ws/src/robot_assembler/meshes/fr12_h103.dae" scale="1.000000 1.000000 1.000000"/>
     </geometry>
  </visual>
  <collision>
     <origin xyz="0.000000 0.000000 -0.019000" rpy="0.61547971 1.57079633 -2.52611294"/>
     <geometry>
     <mesh filename="file:///home/y-kawamura/ros/new_ws/src/robot_assembler/meshes/fr12_h103.dae" scale="1.000000 1.000000 1.000000"/>
     </geometry>
  </collision>
  <visual>
     <origin xyz="0.000000 -0.074500 -0.019000" rpy="-0.48522699 -1.57079633 -1.08556933"/>
     <geometry>
     <mesh filename="file:///home/y-kawamura/ros/new_ws/src/robot_assembler/meshes/fr12_s102.dae" scale="1.000000 1.000000 1.000000"/>
     </geometry>
  </visual>
  <collision>
     <origin xyz="0.000000 -0.074500 -0.019000" rpy="-0.48522699 -1.57079633 -1.08556933"/>
     <geometry>
     <mesh filename="file:///home/y-kawamura/ros/new_ws/src/robot_assembler/meshes/fr12_s102.dae" scale="1.000000 1.000000 1.000000"/>
     </geometry>
  </collision>
  <visual>
     <origin xyz="0.000000 -0.095500 -0.019000" rpy="-0.00000000 -0.00000000 -3.14159265"/>
     <geometry>
     <mesh filename="file:///home/y-kawamura/ros/new_ws/src/robot_assembler/meshes/xm430_dynamixel.dae" scale="1.000000 1.000000 1.000000"/>
     </geometry>
  </visual>
  <collision>
     <origin xyz="0.000000 -0.095500 -0.019000" rpy="-0.00000000 -0.00000000 -3.14159265"/>
     <geometry>
     <mesh filename="file:///home/y-kawamura/ros/new_ws/src/robot_assembler/meshes/xm430_dynamixel.dae" scale="1.000000 1.000000 1.000000"/>
     </geometry>
  </collision>
  </link>
  <xacro:gazebo_link_reference link_name="LINK3" />
  <link name="LINK3">
  <inertial>
     <mass value="0.035"/>
     <origin rpy="0 0 0" xyz="3.045183e-17 0.037793 -0.019"/>
     <inertia ixx="2.398520e-05" ixy="-2.409884e-20" ixz="-4.260739e-21" iyy="7.029167e-06" iyz="-4.384331e-21" izz="2.676187e-05"/>
  </inertial>
  <visual>
     <origin xyz="0.000000 0.000000 -0.019000" rpy="0.27564280 1.57079633 0.27564280"/>
     <geometry>
     <mesh filename="file:///home/y-kawamura/ros/new_ws/src/robot_assembler/meshes/fr12_h101.dae" scale="1.000000 1.000000 1.000000"/>
     </geometry>
  </visual>
  <collision>
     <origin xyz="0.000000 0.000000 -0.019000" rpy="0.27564280 1.57079633 0.27564280"/>
     <geometry>
     <mesh filename="file:///home/y-kawamura/ros/new_ws/src/robot_assembler/meshes/fr12_h101.dae" scale="1.000000 1.000000 1.000000"/>
     </geometry>
  </collision>
  <visual>
     <origin xyz="0.000000 0.083000 -0.019000" rpy="-3.10002210 1.57079633 0.04157055"/>
     <geometry>
     <mesh filename="file:///home/y-kawamura/ros/new_ws/src/robot_assembler/meshes/fr12_h103.dae" scale="1.000000 1.000000 1.000000"/>
     </geometry>
  </visual>
  <collision>
     <origin xyz="0.000000 0.083000 -0.019000" rpy="-3.10002210 1.57079633 0.04157055"/>
     <geometry>
     <mesh filename="file:///home/y-kawamura/ros/new_ws/src/robot_assembler/meshes/fr12_h103.dae" scale="1.000000 1.000000 1.000000"/>
     </geometry>
  </collision>
  </link>
  <xacro:gazebo_link_reference link_name="LINK4" />
  <link name="LINK4">
    <inertial>
      <mass value="1.0"/>
      <!-- <mass value="0.212"/> -->
      <origin rpy="0 0 0" xyz="0.046 -0.012283 -0.018292"/>
     <!-- <origin rpy="0 0 0" xyz="0.019312 -0.012283 -0.018292"/> -->
     <inertia ixx="5.942872e-05" ixy="2.617925e-07" ixz="2.896769e-06" iyy="0.000116" iyz="-4.245283e-08" izz="0.000132"/>
  </inertial>
  <visual>
     <origin xyz="0.000000 0.000000 -0.019000" rpy="-0.00000000 -0.00000000 0.00000000"/>
     <geometry>
     <mesh filename="file:///home/y-kawamura/ros/new_ws/src/robot_assembler/meshes/xm430_dynamixel.dae" scale="1.000000 1.000000 1.000000"/>
     </geometry>
  </visual>
  <collision>
     <origin xyz="0.000000 0.000000 -0.019000" rpy="-0.00000000 -0.00000000 0.00000000"/>
     <geometry>
     <mesh filename="file:///home/y-kawamura/ros/new_ws/src/robot_assembler/meshes/xm430_dynamixel.dae" scale="1.000000 1.000000 1.000000"/>
     </geometry>
  </collision>
  <visual>
     <origin xyz="0.036600 0.000000 -0.019000" rpy="-2.17778399 -1.57079633 -2.53460499"/>
     <geometry>
     <mesh filename="file:///home/y-kawamura/ros/new_ws/src/robot_assembler/meshes/fr12_x102.dae" scale="1.000000 1.000000 1.000000"/>
     </geometry>
  </visual>
  <collision>
     <origin xyz="0.036600 0.000000 -0.019000" rpy="-2.17778399 -1.57079633 -2.53460499"/>
     <geometry>
     <mesh filename="file:///home/y-kawamura/ros/new_ws/src/robot_assembler/meshes/fr12_x102.dae" scale="1.000000 1.000000 1.000000"/>
     </geometry>
  </collision>
  <visual>
     <origin xyz="0.039600 0.000000 -0.019000" rpy="2.37025257 -1.57079633 -2.37025257"/>
     <geometry>
     <mesh filename="file:///home/y-kawamura/ros/new_ws/src/robot_assembler/meshes/xm430_dynamixel.dae" scale="1.000000 1.000000 1.000000"/>
     </geometry>
  </visual>
  <collision>
     <origin xyz="0.039600 0.000000 -0.019000" rpy="2.37025257 -1.57079633 -2.37025257"/>
     <geometry>
     <mesh filename="file:///home/y-kawamura/ros/new_ws/src/robot_assembler/meshes/xm430_dynamixel.dae" scale="1.000000 1.000000 1.000000"/>
     </geometry>
  </collision>
  </link>
  <xacro:gazebo_link_reference link_name="LINK5" />
  <link name="LINK5">
  <inertial>
     <mass value="0.115"/>
     <origin rpy="0 0 0" xyz="0.001304 0.04632 -0.019"/>
     <inertia ixx="4.539431e-05" ixy="-7.395652e-07" ixz="-8.176568e-21" iyy="2.381893e-05" iyz="-5.269639e-21" izz="5.385323e-05"/>
  </inertial>
  <visual>
     <origin xyz="0.000000 0.000000 -0.019000" rpy="0.00000000 1.57079633 0.00000000"/>
     <geometry>
     <mesh filename="file:///home/y-kawamura/ros/new_ws/src/robot_assembler/meshes/fr12_h101.dae" scale="1.000000 1.000000 1.000000"/>
     </geometry>
  </visual>
  <collision>
     <origin xyz="0.000000 0.000000 -0.019000" rpy="0.00000000 1.57079633 0.00000000"/>
     <geometry>
     <mesh filename="file:///home/y-kawamura/ros/new_ws/src/robot_assembler/meshes/fr12_h101.dae" scale="1.000000 1.000000 1.000000"/>
     </geometry>
  </collision>
  <visual>
     <origin xyz="-0.000000 0.063250 -0.019000" rpy="0.14048970 1.57079633 0.14048970"/>
     <geometry>
     <mesh filename="file:///home/y-kawamura/ros/new_ws/src/robot_assembler/meshes/xm430_dynamixel.dae" scale="1.000000 1.000000 1.000000"/>
     </geometry>
  </visual>
  <collision>
     <origin xyz="-0.000000 0.063250 -0.019000" rpy="0.14048970 1.57079633 0.14048970"/>
     <geometry>
     <mesh filename="file:///home/y-kawamura/ros/new_ws/src/robot_assembler/meshes/xm430_dynamixel.dae" scale="1.000000 1.000000 1.000000"/>
     </geometry>
  </collision>
  </link>
  <xacro:gazebo_link_reference link_name="LINK6"/>
  <link name="LINK6">
  <inertial>
    <mass value="1.0"/>
    <origin rpy="0 -0.00000000 -0.00000000" xyz="-0.00000 -0.000000 0.000000"/>
     <!-- <origin rpy="-1.57079633 -0.00000000 -0.00000000" xyz="-0.050000 -0.050000 0.010000"/> -->
     <inertia ixx="3.202708e-05" ixy="-1.817735e-35" ixz="1.637277e-35" iyy="2.478750e-05" iyz="2.894099e-21" izz="2.077708e-05"/>
  </inertial>
  <visual>
     <origin xyz="-0.050000 -0.050000 0.010000" rpy="-1.57079633 -0.00000000 0.00000000"/>
     <geometry>
     <mesh filename="file:///home/y-kawamura/ros/new_ws/src/robot_assembler/meshes/wheel.dae" scale="0.001000 0.001000 0.001000"/>
     </geometry>
  </visual>
  <collision>
     <origin xyz="-0.050000 -0.050000 0.010000" rpy="-1.57079633 -0.00000000 0.00000000"/>
     <geometry>
     <mesh filename="file:///home/y-kawamura/ros/new_ws/src/robot_assembler/meshes/wheel.dae" scale="0.001000 0.001000 0.001000"/>
     </geometry>
  </collision>
  </link>
  <xacro:gazebo_link_reference link_name="LINK7" />
  <link name="LINK7">
  <inertial>
     <mass value="0.015"/>
     <origin rpy="0 0 0" xyz="-2.131628e-17 5.329071e-18 0.01455"/>
     <inertia ixx="1.969763e-06" ixy="-6.539435e-22" ixz="-1.064176e-21" iyy="3.159763e-06" iyz="-6.260938e-37" izz="3.012500e-06"/>
  </inertial>
  <visual>
     <origin xyz="-0.000000 0.000000 0.028000" rpy="-1.57079633 0.00000000 -1.57079633"/>
     <geometry>
     <mesh filename="file:///home/y-kawamura/ros/new_ws/src/robot_assembler/meshes/fr12_h101.dae" scale="1.000000 1.000000 1.000000"/>
     </geometry>
  </visual>
  <collision>
     <origin xyz="-0.000000 0.000000 0.028000" rpy="-1.57079633 0.00000000 -1.57079633"/>
     <geometry>
     <mesh filename="file:///home/y-kawamura/ros/new_ws/src/robot_assembler/meshes/fr12_h101.dae" scale="1.000000 1.000000 1.000000"/>
     </geometry>
  </collision>
  </link>
  <xacro:gazebo_link_reference link_name="LINK8" />
  <link name="LINK8">
  <inertial>
     <mass value="0.212"/>
     <origin rpy="0 0 0" xyz="-0.000708 -0.012283 0.001288"/>
     <inertia ixx="0.000132" ixy="4.245283e-08" ixz="2.896769e-06" iyy="0.000116" iyz="-2.617925e-07" izz="5.942872e-05"/>
  </inertial>
  <visual>
     <origin xyz="0.000000 0.000000 -0.019000" rpy="0.00000000 -0.00000000 0.00000000"/>
     <geometry>
     <mesh filename="file:///home/y-kawamura/ros/new_ws/src/robot_assembler/meshes/xm430_dynamixel.dae" scale="1.000000 1.000000 1.000000"/>
     </geometry>
  </visual>
  <collision>
     <origin xyz="0.000000 0.000000 -0.019000" rpy="0.00000000 -0.00000000 0.00000000"/>
     <geometry>
     <mesh filename="file:///home/y-kawamura/ros/new_ws/src/robot_assembler/meshes/xm430_dynamixel.dae" scale="1.000000 1.000000 1.000000"/>
     </geometry>
  </collision>
  <visual>
     <origin xyz="0.000000 0.000000 -0.016000" rpy="1.57079633 0.00000000 0.00000000"/>
     <geometry>
     <mesh filename="file:///home/y-kawamura/ros/new_ws/src/robot_assembler/meshes/fr12_x102.dae" scale="1.000000 1.000000 1.000000"/>
     </geometry>
  </visual>
  <collision>
     <origin xyz="0.000000 0.000000 -0.016000" rpy="1.57079633 0.00000000 0.00000000"/>
     <geometry>
     <mesh filename="file:///home/y-kawamura/ros/new_ws/src/robot_assembler/meshes/fr12_x102.dae" scale="1.000000 1.000000 1.000000"/>
     </geometry>
  </collision>
  <visual>
     <origin xyz="0.000000 0.000000 0.020600" rpy="-0.03118577 -1.57079633 0.03118577"/>
     <geometry>
     <mesh filename="file:///home/y-kawamura/ros/new_ws/src/robot_assembler/meshes/xm430_dynamixel.dae" scale="1.000000 1.000000 1.000000"/>
     </geometry>
  </visual>
  <collision>
     <origin xyz="0.000000 0.000000 0.020600" rpy="-0.03118577 -1.57079633 0.03118577"/>
     <geometry>
     <mesh filename="file:///home/y-kawamura/ros/new_ws/src/robot_assembler/meshes/xm430_dynamixel.dae" scale="1.000000 1.000000 1.000000"/>
     </geometry>
  </collision>
  </link>
  <xacro:gazebo_link_reference link_name="LINK9" />
  <link name="LINK9">
  <inertial>
     <mass value="0.134"/>
     <origin rpy="0 0 0" xyz="2.055271e-16 -0.072683 -0.017881"/>
     <inertia ixx="9.582042e-05" ixy="2.478839e-19" ixz="-2.077011e-20" iyy="2.736267e-05" iyz="1.622575e-06" izz="8.942792e-05"/>
  </inertial>
  <visual>
     <origin xyz="0.000000 0.000000 -0.019000" rpy="0.61547971 1.57079633 -2.52611294"/>
     <geometry>
     <mesh filename="file:///home/y-kawamura/ros/new_ws/src/robot_assembler/meshes/fr12_h103.dae" scale="1.000000 1.000000 1.000000"/>
     </geometry>
  </visual>
  <collision>
     <origin xyz="0.000000 0.000000 -0.019000" rpy="0.61547971 1.57079633 -2.52611294"/>
     <geometry>
     <mesh filename="file:///home/y-kawamura/ros/new_ws/src/robot_assembler/meshes/fr12_h103.dae" scale="1.000000 1.000000 1.000000"/>
     </geometry>
  </collision>
  <visual>
     <origin xyz="0.000000 -0.074500 -0.019000" rpy="-0.48522699 -1.57079633 -1.08556933"/>
     <geometry>
     <mesh filename="file:///home/y-kawamura/ros/new_ws/src/robot_assembler/meshes/fr12_s102.dae" scale="1.000000 1.000000 1.000000"/>
     </geometry>
  </visual>
  <collision>
     <origin xyz="0.000000 -0.074500 -0.019000" rpy="-0.48522699 -1.57079633 -1.08556933"/>
     <geometry>
     <mesh filename="file:///home/y-kawamura/ros/new_ws/src/robot_assembler/meshes/fr12_s102.dae" scale="1.000000 1.000000 1.000000"/>
     </geometry>
  </collision>
  <visual>
     <origin xyz="0.000000 -0.095500 -0.019000" rpy="-0.00000000 -0.00000000 -3.14159265"/>
     <geometry>
     <mesh filename="file:///home/y-kawamura/ros/new_ws/src/robot_assembler/meshes/xm430_dynamixel.dae" scale="1.000000 1.000000 1.000000"/>
     </geometry>
  </visual>
  <collision>
     <origin xyz="0.000000 -0.095500 -0.019000" rpy="-0.00000000 -0.00000000 -3.14159265"/>
     <geometry>
     <mesh filename="file:///home/y-kawamura/ros/new_ws/src/robot_assembler/meshes/xm430_dynamixel.dae" scale="1.000000 1.000000 1.000000"/>
     </geometry>
  </collision>
  </link>
  <xacro:gazebo_link_reference link_name="LINK10" />
  <link name="LINK10">
  <inertial>
     <mass value="0.035"/>
     <origin rpy="0 0 0" xyz="3.045183e-17 0.037793 -0.019"/>
     <inertia ixx="2.398520e-05" ixy="-2.409884e-20" ixz="-4.260739e-21" iyy="7.029167e-06" iyz="-1.789835e-21" izz="2.676187e-05"/>
  </inertial>
  <visual>
     <origin xyz="0.000000 0.000000 -0.019000" rpy="0.27564280 1.57079633 0.27564280"/>
     <geometry>
     <mesh filename="file:///home/y-kawamura/ros/new_ws/src/robot_assembler/meshes/fr12_h101.dae" scale="1.000000 1.000000 1.000000"/>
     </geometry>
  </visual>
  <collision>
     <origin xyz="0.000000 0.000000 -0.019000" rpy="0.27564280 1.57079633 0.27564280"/>
     <geometry>
     <mesh filename="file:///home/y-kawamura/ros/new_ws/src/robot_assembler/meshes/fr12_h101.dae" scale="1.000000 1.000000 1.000000"/>
     </geometry>
  </collision>
  <visual>
     <origin xyz="0.000000 0.083000 -0.019000" rpy="-3.10002210 1.57079633 0.04157055"/>
     <geometry>
     <mesh filename="file:///home/y-kawamura/ros/new_ws/src/robot_assembler/meshes/fr12_h103.dae" scale="1.000000 1.000000 1.000000"/>
     </geometry>
  </visual>
  <collision>
     <origin xyz="0.000000 0.083000 -0.019000" rpy="-3.10002210 1.57079633 0.04157055"/>
     <geometry>
     <mesh filename="file:///home/y-kawamura/ros/new_ws/src/robot_assembler/meshes/fr12_h103.dae" scale="1.000000 1.000000 1.000000"/>
     </geometry>
  </collision>
  </link>
  <xacro:gazebo_link_reference link_name="LINK11" />
  <link name="LINK11">
    <inertial>
      <mass value="1.0"/>
      <!-- <mass value="0.212"/> -->
      <origin rpy="0 0 0" xyz="0.046 -0.012283 -0.018292"/>
     <!-- <origin rpy="0 0 0" xyz="0.019312 -0.012283 -0.018292"/> -->
     <inertia ixx="5.942872e-05" ixy="2.617925e-07" ixz="2.896769e-06" iyy="0.000116" iyz="-4.245283e-08" izz="0.000132"/>
  </inertial>
  <visual>
     <origin xyz="-0.000000 0.000000 -0.019000" rpy="-0.00000000 -0.00000000 0.00000000"/>
     <geometry>
     <mesh filename="file:///home/y-kawamura/ros/new_ws/src/robot_assembler/meshes/xm430_dynamixel.dae" scale="1.000000 1.000000 1.000000"/>
     </geometry>
  </visual>
  <collision>
     <origin xyz="-0.000000 0.000000 -0.019000" rpy="-0.00000000 -0.00000000 0.00000000"/>
     <geometry>
     <mesh filename="file:///home/y-kawamura/ros/new_ws/src/robot_assembler/meshes/xm430_dynamixel.dae" scale="1.000000 1.000000 1.000000"/>
     </geometry>
  </collision>
  <visual>
     <origin xyz="0.036600 0.000000 -0.019000" rpy="-2.17778399 -1.57079633 -2.53460499"/>
     <geometry>
     <mesh filename="file:///home/y-kawamura/ros/new_ws/src/robot_assembler/meshes/fr12_x102.dae" scale="1.000000 1.000000 1.000000"/>
     </geometry>
  </visual>
  <collision>
     <origin xyz="0.036600 0.000000 -0.019000" rpy="-2.17778399 -1.57079633 -2.53460499"/>
     <geometry>
     <mesh filename="file:///home/y-kawamura/ros/new_ws/src/robot_assembler/meshes/fr12_x102.dae" scale="1.000000 1.000000 1.000000"/>
     </geometry>
  </collision>
  <visual>
     <origin xyz="0.039600 0.000000 -0.019000" rpy="2.37025257 -1.57079633 -2.37025257"/>
     <geometry>
     <mesh filename="file:///home/y-kawamura/ros/new_ws/src/robot_assembler/meshes/xm430_dynamixel.dae" scale="1.000000 1.000000 1.000000"/>
     </geometry>
  </visual>
  <collision>
     <origin xyz="0.039600 0.000000 -0.019000" rpy="2.37025257 -1.57079633 -2.37025257"/>
     <geometry>
     <mesh filename="file:///home/y-kawamura/ros/new_ws/src/robot_assembler/meshes/xm430_dynamixel.dae" scale="1.000000 1.000000 1.000000"/>
     </geometry>
  </collision>
  </link>
  <xacro:gazebo_link_reference link_name="LINK12" />
  <link name="LINK12">
  <inertial>
     <mass value="0.115"/>
     <origin rpy="0 0 0" xyz="-0.001304 0.04632 -0.019"/>
     <inertia ixx="4.539431e-05" ixy="7.395652e-07" ixz="-8.841303e-21" iyy="2.381893e-05" iyz="-1.766354e-21" izz="5.385323e-05"/>
  </inertial>
  <visual>
     <origin xyz="0.000000 0.000000 -0.019000" rpy="0.00000000 1.57079633 0.00000000"/>
     <geometry>
     <mesh filename="file:///home/y-kawamura/ros/new_ws/src/robot_assembler/meshes/fr12_h101.dae" scale="1.000000 1.000000 1.000000"/>
     </geometry>
  </visual>
  <collision>
     <origin xyz="0.000000 0.000000 -0.019000" rpy="0.00000000 1.57079633 0.00000000"/>
     <geometry>
     <mesh filename="file:///home/y-kawamura/ros/new_ws/src/robot_assembler/meshes/fr12_h101.dae" scale="1.000000 1.000000 1.000000"/>
     </geometry>
  </collision>
  <visual>
     <origin xyz="-0.000000 0.063250 -0.019000" rpy="3.01372919 -1.57079633 -3.01372919"/>
     <geometry>
     <mesh filename="file:///home/y-kawamura/ros/new_ws/src/robot_assembler/meshes/xm430_dynamixel.dae" scale="1.000000 1.000000 1.000000"/>
     </geometry>
  </visual>
  <collision>
     <origin xyz="-0.000000 0.063250 -0.019000" rpy="3.01372919 -1.57079633 -3.01372919"/>
     <geometry>
     <mesh filename="file:///home/y-kawamura/ros/new_ws/src/robot_assembler/meshes/xm430_dynamixel.dae" scale="1.000000 1.000000 1.000000"/>
     </geometry>
  </collision>
  </link>
  <xacro:gazebo_link_reference link_name="LINK13" />
  <link name="LINK13">
  <inertial>
    <mass value="1.0"/>
    <origin rpy="0 -0.00000000 -0.00000000" xyz="-0.00000 -0.000000 0.000000"/>
     <!-- <origin rpy="-1.57079633 -0.00000000 -0.00000000" xyz="-0.050000 -0.050000 0.010000"/> -->
     <inertia ixx="3.202708e-05" ixy="-5.636506e-35" ixz="7.107553e-35" iyy="2.478750e-05" iyz="2.894099e-21" izz="2.077708e-05"/>     
  </inertial>
  <visual>
     <origin xyz="-0.050000 -0.050000 0.010000" rpy="-1.57079633 -0.00000000 -0.00000000"/>
     <geometry>
     <mesh filename="file:///home/y-kawamura/ros/new_ws/src/robot_assembler/meshes/wheel.dae" scale="0.001000 0.001000 0.001000"/>
     </geometry>
  </visual>
  <collision>
     <origin xyz="-0.050000 -0.050000 0.010000" rpy="-1.57079633 -0.00000000 -0.00000000"/>
     <geometry>
     <mesh filename="file:///home/y-kawamura/ros/new_ws/src/robot_assembler/meshes/wheel.dae" scale="0.001000 0.001000 0.001000"/>
     </geometry>
  </collision>
  </link>
  <xacro:gazebo_transmission joint_name="JOINT0" />
  <joint name="JOINT0" type="revolute">
     <parent link="BASE"/>
     <child link="LINK0"/>
     <origin xyz="0.012000 -0.032000 -0.040000" rpy="3.14159265 0.00000000 1.57079633"/>
     <axis xyz="0 0 1"/>
     <limit effort="200" lower="0" upper="0" velocity="40"/>
     <!-- <limit effort="200" lower="-3.14159" upper="3.14159" velocity="40"/> -->
  </joint>
  <xacro:gazebo_transmission joint_name="JOINT1" />
  <joint name="JOINT1" type="revolute">
     <parent link="LINK0"/>
     <child link="LINK1"/>
     <origin xyz="-0.000000 -0.020500 0.028000" rpy="-1.57079633 -0.00000000 0.00000000"/>
     <axis xyz="0 0 1"/>
     <limit effort="200" lower="0" upper="0" velocity="40"/>
     <!-- <limit effort="200" lower="-3.14159" upper="3.14159" velocity="40"/> -->
  </joint>
  <xacro:gazebo_transmission joint_name="JOINT2" />
  <joint name="JOINT2" type="revolute">
     <parent link="LINK1"/>
     <child link="LINK2"/>
     <origin xyz="-0.019000 -0.000000 0.020600" rpy="-0.03118577 -1.57079633 0.03118577"/>
     <axis xyz="0 0 1"/>
     <limit effort="200" lower="0" upper="0" velocity="40"/>
     <!-- <limit effort="200" lower="-3.14159" upper="3.14159" velocity="40"/> -->
  </joint>
  <xacro:gazebo_transmission joint_name="JOINT3" />
  <joint name="JOINT3" type="revolute">
     <parent link="LINK2"/>
     <child link="LINK3"/>
     <origin xyz="0.000000 -0.095500 -0.000000" rpy="-0.00000000 -0.00000000 -3.14159265"/>
     <axis xyz="0 0 1"/>
     <limit effort="200" lower="0" upper="0" velocity="40"/>
     <!-- <limit effort="200" lower="-3.14159" upper="3.14159" velocity="40"/> -->
  </joint>
  <xacro:gazebo_transmission joint_name="JOINT4" />
  <joint name="JOINT4" type="revolute">
     <parent link="LINK3"/>
     <child link="LINK4"/>
     <origin xyz="0.000000 0.083000 0.000000" rpy="0.00000000 -0.00000000 0.00000000"/>
     <axis xyz="0 0 1"/>
     <limit effort="200" lower="0" upper="0" velocity="40"/>
     <!-- <limit effort="200" lower="-3.14159" upper="3.14159" velocity="40"/> -->
  </joint>
  <xacro:gazebo_transmission joint_name="JOINT5" />
  <joint name="JOINT5" type="revolute">
     <parent link="LINK4"/>
     <child link="LINK5"/>
     <origin xyz="0.020600 0.000000 -0.019000" rpy="2.37025257 -1.57079633 -2.37025257"/>
     <axis xyz="0 0 1"/>
     <limit effort="200" lower="0" upper="0" velocity="40"/>
     <!-- <limit effort="200" lower="-3.14159" upper="3.14159" velocity="40"/> -->
  </joint>
  <xacro:gazebo_transmission joint_name="JOINT6" />
  <joint name="JOINT6" type="continuous">
     <parent link="LINK5"/>
     <child link="LINK6"/>
     <origin xyz="0.019000 0.063250 -0.019000" rpy="0.14048970 1.57079633 0.14048970"/>
     <axis xyz="0 0 1"/>
     <!-- <limit effort="200" lower="-3.14159" upper="3.14159" velocity="40"/> -->
     <limit effort="200" velocity="40"/>
  </joint>
  <xacro:gazebo_transmission joint_name="JOINT7" />
  <joint name="JOINT7" type="revolute">
     <parent link="BASE"/>
     <child link="LINK7"/>
     <origin xyz="0.012000 0.032000 -0.040000" rpy="3.14159265 0.00000000 1.57079633"/>
     <axis xyz="0 0 1"/>
     <limit effort="200" lower="0" upper="0" velocity="40"/>
     <!-- <limit effort="200" lower="-3.14159" upper="3.14159" velocity="40"/>; -->
  </joint>
  <xacro:gazebo_transmission joint_name="JOINT8" />
  <joint name="JOINT8" type="revolute">
     <parent link="LINK7"/>
     <child link="LINK8"/>
     <origin xyz="-0.000000 -0.020500 0.028000" rpy="-1.57079633 -0.00000000 0.00000000"/>
     <axis xyz="0 0 1"/>
     <limit effort="200" lower="0" upper="0" velocity="40"/>
     <!-- <limit effort="200" lower="-3.14159" upper="3.14159" velocity="40"/> -->
  </joint>
  <xacro:gazebo_transmission joint_name="JOINT9" />
  <joint name="JOINT9" type="revolute">
     <parent link="LINK8"/>
     <child link="LINK9"/>
     <origin xyz="-0.019000 0.000000 0.020600" rpy="-0.03118577 -1.57079633 0.03118577"/>
     <axis xyz="0 0 1"/>
     <limit effort="200" lower="0" upper="0" velocity="40"/>
     <!-- <limit effort="200" lower="-3.14159" upper="3.14159" velocity="40"/> -->
  </joint>
  <xacro:gazebo_transmission joint_name="JOINT10" />
  <joint name="JOINT10" type="revolute">
     <parent link="LINK9"/>
     <child link="LINK10"/>
     <origin xyz="0.000000 -0.095500 -0.000000" rpy="-0.00000000 -0.00000000 -3.14159265"/>
     <axis xyz="0 0 1"/>
     <limit effort="200" lower="0" upper="0" velocity="40"/>
     <!-- <limit effort="200" lower="-3.14159" upper="3.14159" velocity="40"/> -->
  </joint>
  <xacro:gazebo_transmission joint_name="JOINT11" />
  <joint name="JOINT11" type="revolute">
     <parent link="LINK10"/>
     <child link="LINK11"/>
     <origin xyz="0.000000 0.083000 0.000000" rpy="0.00000000 -0.00000000 0.00000000"/>
     <axis xyz="0 0 1"/>
     <limit effort="200" lower="0" upper="0" velocity="40"/>
     <!-- <limit effort="200" lower="-3.14159" upper="3.14159" velocity="40"/> -->
  </joint>
  <xacro:gazebo_transmission joint_name="JOINT12" />
  <joint name="JOINT12" type="revolute">
     <parent link="LINK11"/>
     <child link="LINK12"/>
     <origin xyz="0.020600 0.000000 -0.019000" rpy="2.37025257 -1.57079633 -2.37025257"/>
     <axis xyz="0 0 1"/>
     <limit effort="200" lower="0" upper="0" velocity="40"/>
     <!-- <limit effort="200" lower="-3.14159" upper="3.14159" velocity="40"/> -->
  </joint>
  <xacro:gazebo_transmission joint_name="JOINT13" />
  <joint name="JOINT13" type="continuous">
     <parent link="LINK12"/>
     <child link="LINK13"/>
     <origin xyz="-0.019000 0.063250 -0.019000" rpy="3.01372919 -1.57079633 -3.01372919"/>
     <axis xyz="0 0 1"/>
     <!-- <limit effort="200" lower="-3.14159" upper="3.14159" velocity="40"/> -->
     <limit effort="200" velocity="40"/>
  </joint>

  <!-- Gazebo plugin for ROS Control -->
  <gazebo>
    <plugin name="gazebo_ros_control" filename="libgazebo_ros_control.so">
      <robotNamespace>/wheeled_robot</robotNamespace>
      <robotSimType>gazebo_ros_control/DefaultRobotHWSim</robotSimType>
    </plugin>
  </gazebo>
</robot>
